Workbook

Sheet Report
A1: INSULATION RESISTANCE TEST REPORT
A2: Timed test (15 s, 30 s, 45 s, 60 s, 10 min) with temperature correction, DAR, polarization index and IEEE 43 minimums
A3: Enter data in the blue-on-yellow cells. Grey cells are calculated and locked (sheet protection has no password: Review > Unprotect Sheet).
A5: 1. Job and machine details
A6: Customer / site | E6: Equipment ID / tag
A7: Machine / cable description | E7: Test date
A8: Rated line voltage (kV) | E8: Winding class (sets minimum IR)
A9: Thermal class of insulation | E9: Test voltage applied (V DC)
A10: Winding / insulation temperature (°C) | E10: Ambient temperature (°C) and humidity (%)
A11: Test instrument model | E11: Instrument serial number and calibration due
A12: Tested by | E12: Witnessed or reviewed by
A14: 2. Timed readings and calculated values
A15: Connection tested (for example U to E, V and W earthed) | B15: 15 s (MΩ) | C15: 30 s (MΩ) | D15: 45 s (MΩ) | E15: 60 s (MΩ) | F15: 10 min (MΩ) | G15: Leakage at 1 min (µA) | H15: Temp. factor Kt | I15: IR 1 min at 40 °C (MΩ) | J15: DAR (60 s / 30 s) | K15: PI (10 min / 1 min)
G16: =IF(AND(ISNUMBER(E16),E16>0,ISNUMBER($G$9)),$G$9/E16,"") | H16: =IF(AND(ISNUMBER(E16),ISNUMBER($B$10)),0.5^((Reference!$B$12-$B$10)/Reference!$B$13),"") | I16: =IF(H16="","",E16*H16) | J16: =IF(AND(ISNUMBER(E16),ISNUMBER(C16),C16>0),E16/C16,"") | K16: =IF(AND(ISNUMBER(F16),ISNUMBER(E16),E16>0),F16/E16,"")
G17: =IF(AND(ISNUMBER(E17),E17>0,ISNUMBER($G$9)),$G$9/E17,"") | H17: =IF(AND(ISNUMBER(E17),ISNUMBER($B$10)),0.5^((Reference!$B$12-$B$10)/Reference!$B$13),"") | I17: =IF(H17="","",E17*H17) | J17: =IF(AND(ISNUMBER(E17),ISNUMBER(C17),C17>0),E17/C17,"") | K17: =IF(AND(ISNUMBER(F17),ISNUMBER(E17),E17>0),F17/E17,"")
G18: =IF(AND(ISNUMBER(E18),E18>0,ISNUMBER($G$9)),$G$9/E18,"") | H18: =IF(AND(ISNUMBER(E18),ISNUMBER($B$10)),0.5^((Reference!$B$12-$B$10)/Reference!$B$13),"") | I18: =IF(H18="","",E18*H18) | J18: =IF(AND(ISNUMBER(E18),ISNUMBER(C18),C18>0),E18/C18,"") | K18: =IF(AND(ISNUMBER(F18),ISNUMBER(E18),E18>0),F18/E18,"")
G19: =IF(AND(ISNUMBER(E19),E19>0,ISNUMBER($G$9)),$G$9/E19,"") | H19: =IF(AND(ISNUMBER(E19),ISNUMBER($B$10)),0.5^((Reference!$B$12-$B$10)/Reference!$B$13),"") | I19: =IF(H19="","",E19*H19) | J19: =IF(AND(ISNUMBER(E19),ISNUMBER(C19),C19>0),E19/C19,"") | K19: =IF(AND(ISNUMBER(F19),ISNUMBER(E19),E19>0),F19/E19,"")
G20: =IF(AND(ISNUMBER(E20),E20>0,ISNUMBER($G$9)),$G$9/E20,"") | H20: =IF(AND(ISNUMBER(E20),ISNUMBER($B$10)),0.5^((Reference!$B$12-$B$10)/Reference!$B$13),"") | I20: =IF(H20="","",E20*H20) | J20: =IF(AND(ISNUMBER(E20),ISNUMBER(C20),C20>0),E20/C20,"") | K20: =IF(AND(ISNUMBER(F20),ISNUMBER(E20),E20>0),F20/E20,"")
G21: =IF(AND(ISNUMBER(E21),E21>0,ISNUMBER($G$9)),$G$9/E21,"") | H21: =IF(AND(ISNUMBER(E21),ISNUMBER($B$10)),0.5^((Reference!$B$12-$B$10)/Reference!$B$13),"") | I21: =IF(H21="","",E21*H21) | J21: =IF(AND(ISNUMBER(E21),ISNUMBER(C21),C21>0),E21/C21,"") | K21: =IF(AND(ISNUMBER(F21),ISNUMBER(E21),E21>0),F21/E21,"")
A22: Kt = 0.5^((40 - T) / 10). IR at 40 °C = IR at 1 min x Kt. Leakage = test voltage / IR at 1 min. Add rows by copying the last row if you test more connections.
A24: 3. Limits for this machine
A25: Minimum IR at 40 °C, 1 min (MΩ) | B25: =IF(OR(G8="",NOT(ISNUMBER(B8))),"",IF(LEFT(G8,3)="Pre",B8+Reference!$B$7,IF(LEFT(G8,4)="Form",Reference!$B$8,Reference!$B$9))) | C25: IEEE 43-2013: kV + 1, or 100, or 5 MΩ depending on the winding class selected above.
A26: Minimum polarization index | B26: =IF(B9="","",IF(B9="A",Reference!$B$10,Reference!$B$11)) | C26: IEEE 43-2013: 1.5 for thermal class A, 2.0 for B, F and H.
A27: Recommended test voltage (IEEE 43-2013) | B27: =IF(NOT(ISNUMBER(B8)),"",IF(B8<Reference!$A$25,1,IF(B8<=Reference!$A$26,2,IF(B8<=Reference!$A$27,3,IF(B8<=Reference!$A$28,4,5))))) | C27: =IF(B27="","",INDEX(Reference!$B$25:$B$29,B27)) | D27: =IF(B27="","",INDEX(Reference!$C$25:$C$29,B27)) | E27: from / to, V DC (band number is the row in Reference section B)
A28: Test voltage used against recommendation | B28: =IF(OR(C27="",NOT(ISNUMBER(G9))),"",IF(AND(G9>=C27,G9<=D27),"Within recommended range","Outside recommended range - check"))
A30: 4. Evaluation per connection
A31: Connection | B31: IR 1 min at 40 °C (MΩ) | C31: Minimum IR (MΩ) | D31: IR check | E31: DAR class | F31: PI | G31: PI class (guide) | H31: Minimum PI | I31: PI check | J31: Result | K31: Remarks
A32: =IF(A16="","",A16) | B32: =IF(I16="","",I16) | C32: =IF(OR(A16="",$B$25=""),"",$B$25) | D32: =IF(OR(B32="",C32=""),"",IF(B32>=C32,"Meets minimum","Below minimum")) | E32: =IF(J16="","",IF(J16<Reference!$B$15,"Poor",IF(J16<Reference!$B$16,"Questionable",IF(J16<Reference!$B$17,"Acceptable","Excellent")))) | F32: =IF(K16="","",K16) | G32: =IF(F32="","",IF(E16>Reference!$B$14,"Not meaningful",IF(F32<Reference!$B$18,"Dangerous",IF(F32<Reference!$B$19,"Questionable",IF(F32<=Reference!$B$20,"Good","Excellent"))))) | H32: =IF(OR(A16="",$B$26=""),"",$B$26) | I32: =IF(F32="","",IF(E16>Reference!$B$14,"Not applicable",IF(H32="","",IF(F32>=H32,"Meets minimum","Below minimum")))) | J32: =IF(B32="","",IF(D32="","INCOMPLETE",IF(OR(D32="Below minimum",I32="Below minimum"),"BELOW LIMIT",IF(F32="","PASS (IR only)","PASS"))))
A33: =IF(A17="","",A17) | B33: =IF(I17="","",I17) | C33: =IF(OR(A17="",$B$25=""),"",$B$25) | D33: =IF(OR(B33="",C33=""),"",IF(B33>=C33,"Meets minimum","Below minimum")) | E33: =IF(J17="","",IF(J17<Reference!$B$15,"Poor",IF(J17<Reference!$B$16,"Questionable",IF(J17<Reference!$B$17,"Acceptable","Excellent")))) | F33: =IF(K17="","",K17) | G33: =IF(F33="","",IF(E17>Reference!$B$14,"Not meaningful",IF(F33<Reference!$B$18,"Dangerous",IF(F33<Reference!$B$19,"Questionable",IF(F33<=Reference!$B$20,"Good","Excellent"))))) | H33: =IF(OR(A17="",$B$26=""),"",$B$26) | I33: =IF(F33="","",IF(E17>Reference!$B$14,"Not applicable",IF(H33="","",IF(F33>=H33,"Meets minimum","Below minimum")))) | J33: =IF(B33="","",IF(D33="","INCOMPLETE",IF(OR(D33="Below minimum",I33="Below minimum"),"BELOW LIMIT",IF(F33="","PASS (IR only)","PASS"))))
A34: =IF(A18="","",A18) | B34: =IF(I18="","",I18) | C34: =IF(OR(A18="",$B$25=""),"",$B$25) | D34: =IF(OR(B34="",C34=""),"",IF(B34>=C34,"Meets minimum","Below minimum")) | E34: =IF(J18="","",IF(J18<Reference!$B$15,"Poor",IF(J18<Reference!$B$16,"Questionable",IF(J18<Reference!$B$17,"Acceptable","Excellent")))) | F34: =IF(K18="","",K18) | G34: =IF(F34="","",IF(E18>Reference!$B$14,"Not meaningful",IF(F34<Reference!$B$18,"Dangerous",IF(F34<Reference!$B$19,"Questionable",IF(F34<=Reference!$B$20,"Good","Excellent"))))) | H34: =IF(OR(A18="",$B$26=""),"",$B$26) | I34: =IF(F34="","",IF(E18>Reference!$B$14,"Not applicable",IF(H34="","",IF(F34>=H34,"Meets minimum","Below minimum")))) | J34: =IF(B34="","",IF(D34="","INCOMPLETE",IF(OR(D34="Below minimum",I34="Below minimum"),"BELOW LIMIT",IF(F34="","PASS (IR only)","PASS"))))
A35: =IF(A19="","",A19) | B35: =IF(I19="","",I19) | C35: =IF(OR(A19="",$B$25=""),"",$B$25) | D35: =IF(OR(B35="",C35=""),"",IF(B35>=C35,"Meets minimum","Below minimum")) | E35: =IF(J19="","",IF(J19<Reference!$B$15,"Poor",IF(J19<Reference!$B$16,"Questionable",IF(J19<Reference!$B$17,"Acceptable","Excellent")))) | F35: =IF(K19="","",K19) | G35: =IF(F35="","",IF(E19>Reference!$B$14,"Not meaningful",IF(F35<Reference!$B$18,"Dangerous",IF(F35<Reference!$B$19,"Questionable",IF(F35<=Reference!$B$20,"Good","Excellent"))))) | H35: =IF(OR(A19="",$B$26=""),"",$B$26) | I35: =IF(F35="","",IF(E19>Reference!$B$14,"Not applicable",IF(H35="","",IF(F35>=H35,"Meets minimum","Below minimum")))) | J35: =IF(B35="","",IF(D35="","INCOMPLETE",IF(OR(D35="Below minimum",I35="Below minimum"),"BELOW LIMIT",IF(F35="","PASS (IR only)","PASS"))))
A36: =IF(A20="","",A20) | B36: =IF(I20="","",I20) | C36: =IF(OR(A20="",$B$25=""),"",$B$25) | D36: =IF(OR(B36="",C36=""),"",IF(B36>=C36,"Meets minimum","Below minimum")) | E36: =IF(J20="","",IF(J20<Reference!$B$15,"Poor",IF(J20<Reference!$B$16,"Questionable",IF(J20<Reference!$B$17,"Acceptable","Excellent")))) | F36: =IF(K20="","",K20) | G36: =IF(F36="","",IF(E20>Reference!$B$14,"Not meaningful",IF(F36<Reference!$B$18,"Dangerous",IF(F36<Reference!$B$19,"Questionable",IF(F36<=Reference!$B$20,"Good","Excellent"))))) | H36: =IF(OR(A20="",$B$26=""),"",$B$26) | I36: =IF(F36="","",IF(E20>Reference!$B$14,"Not applicable",IF(H36="","",IF(F36>=H36,"Meets minimum","Below minimum")))) | J36: =IF(B36="","",IF(D36="","INCOMPLETE",IF(OR(D36="Below minimum",I36="Below minimum"),"BELOW LIMIT",IF(F36="","PASS (IR only)","PASS"))))
A37: =IF(A21="","",A21) | B37: =IF(I21="","",I21) | C37: =IF(OR(A21="",$B$25=""),"",$B$25) | D37: =IF(OR(B37="",C37=""),"",IF(B37>=C37,"Meets minimum","Below minimum")) | E37: =IF(J21="","",IF(J21<Reference!$B$15,"Poor",IF(J21<Reference!$B$16,"Questionable",IF(J21<Reference!$B$17,"Acceptable","Excellent")))) | F37: =IF(K21="","",K21) | G37: =IF(F37="","",IF(E21>Reference!$B$14,"Not meaningful",IF(F37<Reference!$B$18,"Dangerous",IF(F37<Reference!$B$19,"Questionable",IF(F37<=Reference!$B$20,"Good","Excellent"))))) | H37: =IF(OR(A21="",$B$26=""),"",$B$26) | I37: =IF(F37="","",IF(E21>Reference!$B$14,"Not applicable",IF(H37="","",IF(F37>=H37,"Meets minimum","Below minimum")))) | J37: =IF(B37="","",IF(D37="","INCOMPLETE",IF(OR(D37="Below minimum",I37="Below minimum"),"BELOW LIMIT",IF(F37="","PASS (IR only)","PASS"))))
A39: 5. Result
A40: Overall result | B40: =IF(SUMPRODUCT(--(LEN(J32:J37)>0))=0,"",IF(COUNTIF(J32:J37,"BELOW LIMIT")>0,"BELOW LIMIT - "&COUNTIF(J32:J37,"BELOW LIMIT")&" of "&SUMPRODUCT(--(LEN(J32:J37)>0))&" connections below the minimum",IF(COUNTIF(J32:J37,"INCOMPLETE")>0,"INCOMPLETE - enter winding class, rated kV and thermal class","PASS - all "&SUMPRODUCT(--(LEN(J32:J37)>0))&" connections meet the minimums")))
A41: Lowest IR at 40 °C across connections (MΩ) | B41: =IF(COUNT(I16:I21)=0,"",MIN(I16:I21))
A42: Lowest PI across connections | B42: =IF(COUNT(K16:K21)=0,"",MIN(K16:K21))
A43: Remarks and recommended action
A46: Signature and date: tester | F46: Reviewer
A48: Method notes
...

Sheet Example
A1: INSULATION RESISTANCE TEST REPORT
A2: Timed test (15 s, 30 s, 45 s, 60 s, 10 min) with temperature correction, DAR, polarization index and IEEE 43 minimums
A3: EXAMPLE with made-up data, to show the expected format. Use the blank sheet for your own report.
A5: 1. Job and machine details
A6: Customer / site | B6: Demo Plant, Howrah | E6: Equipment ID / tag | G6: P-101 pump motor
A7: Machine / cable description | B7: 415 V, 55 kW induction motor, random-wound stator | E7: Test date | G7: 46313
A8: Rated line voltage (kV) | B8: 0.415 | E8: Winding class (sets minimum IR) | G8: Random-wound, or form-wound below 1 kV (5 MΩ)
A9: Thermal class of insulation | B9: F | E9: Test voltage applied (V DC) | G9: 500
A10: Winding / insulation temperature (°C) | B10: 32 | E10: Ambient temperature (°C) and humidity (%) | G10: 30 °C / 68 %
A11: Test instrument model | B11: CIE DIT-2500 | E11: Instrument serial number and calibration due | G11: Sample serial, cal due Mar 2027
A12: Tested by | B12: A. Sample | E12: Witnessed or reviewed by | G12: B. Sample
A14: 2. Timed readings and calculated values
A15: Connection tested (for example U to E, V and W earthed) | B15: 15 s (MΩ) | C15: 30 s (MΩ) | D15: 45 s (MΩ) | E15: 60 s (MΩ) | F15: 10 min (MΩ) | G15: Leakage at 1 min (µA) | H15: Temp. factor Kt | I15: IR 1 min at 40 °C (MΩ) | J15: DAR (60 s / 30 s) | K15: PI (10 min / 1 min)
A16: U to E (V, W earthed) | B16: 180 | C16: 230 | D16: 270 | E16: 300 | F16: 900 | G16: =IF(AND(ISNUMBER(E16),E16>0,ISNUMBER($G$9)),$G$9/E16,"") -> 1.6666667 | H16: =IF(AND(ISNUMBER(E16),ISNUMBER($B$10)),0.5^((Reference!$B$12-$B$10)/Reference!$B$13),"") -> 0.57434918 | I16: =IF(H16="","",E16*H16) -> 172.30475 | J16: =IF(AND(ISNUMBER(E16),ISNUMBER(C16),C16>0),E16/C16,"") -> 1.3043478 | K16: =IF(AND(ISNUMBER(F16),ISNUMBER(E16),E16>0),F16/E16,"") -> 3
A17: V to E (U, W earthed) | B17: 170 | C17: 220 | D17: 260 | E17: 285 | F17: 860 | G17: =IF(AND(ISNUMBER(E17),E17>0,ISNUMBER($G$9)),$G$9/E17,"") -> 1.754386 | H17: =IF(AND(ISNUMBER(E17),ISNUMBER($B$10)),0.5^((Reference!$B$12-$B$10)/Reference!$B$13),"") -> 0.57434918 | I17: =IF(H17="","",E17*H17) -> 163.68952 | J17: =IF(AND(ISNUMBER(E17),ISNUMBER(C17),C17>0),E17/C17,"") -> 1.2954545 | K17: =IF(AND(ISNUMBER(F17),ISNUMBER(E17),E17>0),F17/E17,"") -> 3.0175439
A18: W to E (U, V earthed) | B18: 175 | C18: 225 | D18: 262 | E18: 290 | F18: 870 | G18: =IF(AND(ISNUMBER(E18),E18>0,ISNUMBER($G$9)),$G$9/E18,"") -> 1.7241379 | H18: =IF(AND(ISNUMBER(E18),ISNUMBER($B$10)),0.5^((Reference!$B$12-$B$10)/Reference!$B$13),"") -> 0.57434918 | I18: =IF(H18="","",E18*H18) -> 166.56126 | J18: =IF(AND(ISNUMBER(E18),ISNUMBER(C18),C18>0),E18/C18,"") -> 1.2888889 | K18: =IF(AND(ISNUMBER(F18),ISNUMBER(E18),E18>0),F18/E18,"") -> 3
G19: =IF(AND(ISNUMBER(E19),E19>0,ISNUMBER($G$9)),$G$9/E19,"") | H19: =IF(AND(ISNUMBER(E19),ISNUMBER($B$10)),0.5^((Reference!$B$12-$B$10)/Reference!$B$13),"") | I19: =IF(H19="","",E19*H19) | J19: =IF(AND(ISNUMBER(E19),ISNUMBER(C19),C19>0),E19/C19,"") | K19: =IF(AND(ISNUMBER(F19),ISNUMBER(E19),E19>0),F19/E19,"")
G20: =IF(AND(ISNUMBER(E20),E20>0,ISNUMBER($G$9)),$G$9/E20,"") | H20: =IF(AND(ISNUMBER(E20),ISNUMBER($B$10)),0.5^((Reference!$B$12-$B$10)/Reference!$B$13),"") | I20: =IF(H20="","",E20*H20) | J20: =IF(AND(ISNUMBER(E20),ISNUMBER(C20),C20>0),E20/C20,"") | K20: =IF(AND(ISNUMBER(F20),ISNUMBER(E20),E20>0),F20/E20,"")
G21: =IF(AND(ISNUMBER(E21),E21>0,ISNUMBER($G$9)),$G$9/E21,"") | H21: =IF(AND(ISNUMBER(E21),ISNUMBER($B$10)),0.5^((Reference!$B$12-$B$10)/Reference!$B$13),"") | I21: =IF(H21="","",E21*H21) | J21: =IF(AND(ISNUMBER(E21),ISNUMBER(C21),C21>0),E21/C21,"") | K21: =IF(AND(ISNUMBER(F21),ISNUMBER(E21),E21>0),F21/E21,"")
A22: Kt = 0.5^((40 - T) / 10). IR at 40 °C = IR at 1 min x Kt. Leakage = test voltage / IR at 1 min. Add rows by copying the last row if you test more connections.
A24: 3. Limits for this machine
A25: Minimum IR at 40 °C, 1 min (MΩ) | B25: =IF(OR(G8="",NOT(ISNUMBER(B8))),"",IF(LEFT(G8,3)="Pre",B8+Reference!$B$7,IF(LEFT(G8,4)="Form",Reference!$B$8,Reference!$B$9))) -> 5 | C25: IEEE 43-2013: kV + 1, or 100, or 5 MΩ depending on the winding class selected above.
A26: Minimum polarization index | B26: =IF(B9="","",IF(B9="A",Reference!$B$10,Reference!$B$11)) -> 2 | C26: IEEE 43-2013: 1.5 for thermal class A, 2.0 for B, F and H.
A27: Recommended test voltage (IEEE 43-2013) | B27: =IF(NOT(ISNUMBER(B8)),"",IF(B8<Reference!$A$25,1,IF(B8<=Reference!$A$26,2,IF(B8<=Reference!$A$27,3,IF(B8<=Reference!$A$28,4,5))))) -> 1 | C27: =IF(B27="","",INDEX(Reference!$B$25:$B$29,B27)) -> 500 | D27: =IF(B27="","",INDEX(Reference!$C$25:$C$29,B27)) -> 500 | E27: from / to, V DC (band number is the row in Reference section B)
A28: Test voltage used against recommendation | B28: =IF(OR(C27="",NOT(ISNUMBER(G9))),"",IF(AND(G9>=C27,G9<=D27),"Within recommended range","Outside recommended range - check")) -> Within recommended range
A30: 4. Evaluation per connection
A31: Connection | B31: IR 1 min at 40 °C (MΩ) | C31: Minimum IR (MΩ) | D31: IR check | E31: DAR class | F31: PI | G31: PI class (guide) | H31: Minimum PI | I31: PI check | J31: Result | K31: Remarks
A32: =IF(A16="","",A16) -> U to E (V, W earthed) | B32: =IF(I16="","",I16) -> 172.30475 | C32: =IF(OR(A16="",$B$25=""),"",$B$25) -> 5 | D32: =IF(OR(B32="",C32=""),"",IF(B32>=C32,"Meets minimum","Below minimum")) -> Meets minimum | E32: =IF(J16="","",IF(J16<Reference!$B$15,"Poor",IF(J16<Reference!$B$16,"Questionable",IF(J16<Reference!$B$17,"Acceptable","Excellent")))) -> Acceptable | F32: =IF(K16="","",K16) -> 3 | G32: =IF(F32="","",IF(E16>Reference!$B$14,"Not meaningful",IF(F32<Reference!$B$18,"Dangerous",IF(F32<Reference!$B$19,"Questionable",IF(F32<=Reference!$B$20,"Good","Excellent"))))) -> Good | H32: =IF(OR(A16="",$B$26=""),"",$B$26) -> 2 | I32: =IF(F32="","",IF(E16>Reference!$B$14,"Not applicable",IF(H32="","",IF(F32>=H32,"Meets minimum","Below minimum")))) -> Meets minimum | J32: =IF(B32="","",IF(D32="","INCOMPLETE",IF(OR(D32="Below minimum",I32="Below minimum"),"BELOW LIMIT",IF(F32="","PASS (IR only)","PASS")))) -> PASS
A33: =IF(A17="","",A17) -> V to E (U, W earthed) | B33: =IF(I17="","",I17) -> 163.68952 | C33: =IF(OR(A17="",$B$25=""),"",$B$25) -> 5 | D33: =IF(OR(B33="",C33=""),"",IF(B33>=C33,"Meets minimum","Below minimum")) -> Meets minimum | E33: =IF(J17="","",IF(J17<Reference!$B$15,"Poor",IF(J17<Reference!$B$16,"Questionable",IF(J17<Reference!$B$17,"Acceptable","Excellent")))) -> Acceptable | F33: =IF(K17="","",K17) -> 3.0175439 | G33: =IF(F33="","",IF(E17>Reference!$B$14,"Not meaningful",IF(F33<Reference!$B$18,"Dangerous",IF(F33<Reference!$B$19,"Questionable",IF(F33<=Reference!$B$20,"Good","Excellent"))))) -> Good | H33: =IF(OR(A17="",$B$26=""),"",$B$26) -> 2 | I33: =IF(F33="","",IF(E17>Reference!$B$14,"Not applicable",IF(H33="","",IF(F33>=H33,"Meets minimum","Below minimum")))) -> Meets minimum | J33: =IF(B33="","",IF(D33="","INCOMPLETE",IF(OR(D33="Below minimum",I33="Below minimum"),"BELOW LIMIT",IF(F33="","PASS (IR only)","PASS")))) -> PASS
A34: =IF(A18="","",A18) -> W to E (U, V earthed) | B34: =IF(I18="","",I18) -> 166.56126 | C34: =IF(OR(A18="",$B$25=""),"",$B$25) -> 5 | D34: =IF(OR(B34="",C34=""),"",IF(B34>=C34,"Meets minimum","Below minimum")) -> Meets minimum | E34: =IF(J18="","",IF(J18<Reference!$B$15,"Poor",IF(J18<Reference!$B$16,"Questionable",IF(J18<Reference!$B$17,"Acceptable","Excellent")))) -> Acceptable | F34: =IF(K18="","",K18) -> 3 | G34: =IF(F34="","",IF(E18>Reference!$B$14,"Not meaningful",IF(F34<Reference!$B$18,"Dangerous",IF(F34<Reference!$B$19,"Questionable",IF(F34<=Reference!$B$20,"Good","Excellent"))))) -> Good | H34: =IF(OR(A18="",$B$26=""),"",$B$26) -> 2 | I34: =IF(F34="","",IF(E18>Reference!$B$14,"Not applicable",IF(H34="","",IF(F34>=H34,"Meets minimum","Below minimum")))) -> Meets minimum | J34: =IF(B34="","",IF(D34="","INCOMPLETE",IF(OR(D34="Below minimum",I34="Below minimum"),"BELOW LIMIT",IF(F34="","PASS (IR only)","PASS")))) -> PASS
A35: =IF(A19="","",A19) | B35: =IF(I19="","",I19) | C35: =IF(OR(A19="",$B$25=""),"",$B$25) | D35: =IF(OR(B35="",C35=""),"",IF(B35>=C35,"Meets minimum","Below minimum")) | E35: =IF(J19="","",IF(J19<Reference!$B$15,"Poor",IF(J19<Reference!$B$16,"Questionable",IF(J19<Reference!$B$17,"Acceptable","Excellent")))) | F35: =IF(K19="","",K19) | G35: =IF(F35="","",IF(E19>Reference!$B$14,"Not meaningful",IF(F35<Reference!$B$18,"Dangerous",IF(F35<Reference!$B$19,"Questionable",IF(F35<=Reference!$B$20,"Good","Excellent"))))) | H35: =IF(OR(A19="",$B$26=""),"",$B$26) | I35: =IF(F35="","",IF(E19>Reference!$B$14,"Not applicable",IF(H35="","",IF(F35>=H35,"Meets minimum","Below minimum")))) | J35: =IF(B35="","",IF(D35="","INCOMPLETE",IF(OR(D35="Below minimum",I35="Below minimum"),"BELOW LIMIT",IF(F35="","PASS (IR only)","PASS"))))
A36: =IF(A20="","",A20) | B36: =IF(I20="","",I20) | C36: =IF(OR(A20="",$B$25=""),"",$B$25) | D36: =IF(OR(B36="",C36=""),"",IF(B36>=C36,"Meets minimum","Below minimum")) | E36: =IF(J20="","",IF(J20<Reference!$B$15,"Poor",IF(J20<Reference!$B$16,"Questionable",IF(J20<Reference!$B$17,"Acceptable","Excellent")))) | F36: =IF(K20="","",K20) | G36: =IF(F36="","",IF(E20>Reference!$B$14,"Not meaningful",IF(F36<Reference!$B$18,"Dangerous",IF(F36<Reference!$B$19,"Questionable",IF(F36<=Reference!$B$20,"Good","Excellent"))))) | H36: =IF(OR(A20="",$B$26=""),"",$B$26) | I36: =IF(F36="","",IF(E20>Reference!$B$14,"Not applicable",IF(H36="","",IF(F36>=H36,"Meets minimum","Below minimum")))) | J36: =IF(B36="","",IF(D36="","INCOMPLETE",IF(OR(D36="Below minimum",I36="Below minimum"),"BELOW LIMIT",IF(F36="","PASS (IR only)","PASS"))))
A37: =IF(A21="","",A21) | B37: =IF(I21="","",I21) | C37: =IF(OR(A21="",$B$25=""),"",$B$25) | D37: =IF(OR(B37="",C37=""),"",IF(B37>=C37,"Meets minimum","Below minimum")) | E37: =IF(J21="","",IF(J21<Reference!$B$15,"Poor",IF(J21<Reference!$B$16,"Questionable",IF(J21<Reference!$B$17,"Acceptable","Excellent")))) | F37: =IF(K21="","",K21) | G37: =IF(F37="","",IF(E21>Reference!$B$14,"Not meaningful",IF(F37<Reference!$B$18,"Dangerous",IF(F37<Reference!$B$19,"Questionable",IF(F37<=Reference!$B$20,"Good","Excellent"))))) | H37: =IF(OR(A21="",$B$26=""),"",$B$26) | I37: =IF(F37="","",IF(E21>Reference!$B$14,"Not applicable",IF(H37="","",IF(F37>=H37,"Meets minimum","Below minimum")))) | J37: =IF(B37="","",IF(D37="","INCOMPLETE",IF(OR(D37="Below minimum",I37="Below minimum"),"BELOW LIMIT",IF(F37="","PASS (IR only)","PASS"))))
A39: 5. Result
A40: Overall result | B40: =IF(SUMPRODUCT(--(LEN(J32:J37)>0))=0,"",IF(COUNTIF(J32:J37,"BELOW LIMIT")>0,"BELOW LIMIT - "&COUNTIF(J32:J37,"BELOW LIMIT")&" of "&SUMPRODUCT(--(LEN(J32:J37)>0))&" connections below the minimum",IF(COUNTIF(J32:J37,"INCOMPLETE")>0,"INCOMPLETE - enter winding class, rated kV and thermal class","PASS - all "&SUMPRODUCT(--(LEN(J32:J37)>0))&" connections meet the minimums"))) -> PASS - all 3 connections meet the minimums
A41: Lowest IR at 40 °C across connections (MΩ) | B41: =IF(COUNT(I16:I21)=0,"",MIN(I16:I21)) -> 163.68952
A42: Lowest PI across connections | B42: =IF(COUNT(K16:K21)=0,"",MIN(K16:K21)) -> 3
A43: Remarks and recommended action | B43: Example only. All three windings above the minimum with healthy absorption. Re-test after the next shutdown and compare corrected values.
A46: Signature and date: tester | F46: Reviewer
A48: Method notes
...

Sheet Reference
A1: REFERENCE: constants, limits and sources
A2: Every number used by the Report sheet is listed here once. Blue cells can be edited if your standard or customer specification differs.
A3: Enter data in the blue-on-yellow cells. Grey cells are calculated and locked (sheet protection has no password: Review > Unprotect Sheet).
A5: A. Limits and constants used in the formulas
A6: Item | B6: Value | C6: Unit | D6: Basis
A7: Pre-1970 windings, field windings and others: minimum IR = rated kV + this | B7: 1 | C7: MΩ per kV + 1 | D7: IEEE 43-2013, minimum IR1min for windings not described below (kV + 1 MΩ)
A8: Form-wound coils built after about 1970 (AC) and DC armatures: minimum IR | B8: 100 | C8: MΩ | D8: IEEE 43-2013, minimum IR1min
A9: Random-wound stator coils, and form-wound coils rated below 1 kV: minimum IR | B9: 5 | C9: MΩ | D9: IEEE 43-2013, minimum IR1min
A10: Minimum polarization index, thermal class A | B10: 1.5 | C10: - | D10: IEEE 43-2013, minimum PI by thermal class
A11: Minimum polarization index, thermal class B, F and H | B11: 2 | C11: - | D11: IEEE 43-2013, minimum PI by thermal class
A12: Reference temperature for correction | B12: 40 | C12: °C | D12: IEEE 43-2013 refers readings to 40 °C
A13: Temperature interval over which IR halves | B13: 10 | C13: °C | D13: Usual field rule (Kt = 0.5^((40 - T)/10)). An approximation.
A14: PI not meaningful when IR at 1 min exceeds | B14: 5000 | C14: MΩ | D14: IEEE 43-2013 note on very high readings
A15: DAR boundary: poor / questionable | B15: 1 | C15: - | D15: Common guide band (CIE PI and DAR calculator), not a standard limit
A16: DAR boundary: questionable / acceptable | B16: 1.25 | C16: - | D16: Common guide band, not a standard limit
A17: DAR boundary: acceptable / excellent | B17: 1.6 | C17: - | D17: Common guide band, not a standard limit
A18: PI boundary: dangerous / questionable | B18: 1 | C18: - | D18: Common guide band (CIE PI and DAR calculator), not a standard limit
... A20: PI boundary: good / excellent | B20: 4 | C20: - | D20: Common guide band, not a standard limit
A23: B. Recommended DC test voltage by winding rated voltage (IEEE 43-2013)
A24: Rated line voltage up to (kV) | B24: Test voltage from (V DC) | C24: Test voltage to (V DC) | D24: Band
A25: 1 | B25: 500 | C25: 500 | D25: Below 1 kV (strictly less than)
A26: 2.5 | B26: 500 | C26: 1000 | D26: 1 kV up to and including 2.5 kV
A27: 5 | B27: 1000 | C27: 2500 | D27: Above 2.5 kV up to and including 5 kV
A28: 12 | B28: 2500 | C28: 5000 | D28: Above 5 kV up to and including 12 kV
A29: 1000 | B29: 5000 | C29: 10000 | D29: Above 12 kV
A32: C. Sources, assumptions and limits of use
A33: Sources: IEEE Std 43-2013, Recommended Practice for Testing Insulation Resistance of Electric Machinery (minimum IR, minimum PI, test voltages, temperature correction). The values above were entered from the standard as commonly quoted. Check them against the edition you work to before relying on a result.
A34: These are recommended minimums for in-service rotating machines. They are not a guarantee of health, and a pass with a falling trend still deserves attention. Use the stricter of these limits and your plant or customer specification.
A35: Temperature correction Kt = 0.5^((40 - T) / 10) is a field approximation. For best trending, test at a similar winding temperature each time and record the temperature.
A36: The DAR and PI class names (Poor, Questionable, Good and so on) are common guide bands used by CIE tools, not limits from IEEE 43. Only the minimum PI in section A comes from the standard.
A37: Leakage current at 1 minute is calculated as test voltage / IR (V divided by MΩ gives µA). It is an indication only, not a measurement of the instrument output current.
A38: For cables, transformers and other equipment, use the limits in the relevant standard or manufacturer instruction and edit the blue cells above. The winding-class options on the Report sheet apply to rotating machines.
